WARNING 2024-12-08 15:42:49,174 log Not Found: /favicon.ico
WARNING 2024-12-08 15:42:49,174 basehttp "GET /favicon.ico HTTP/1.1" 404 2528
CRITICAL 2024-12-08 15:45:22,412 views Suspicious login attempt detected
CRITICAL 2024-12-08 15:46:13,497 views Attempt to register with admin username
WARNING 2024-12-09 15:28:09,545 log Not Found: /favicon.ico
WARNING 2024-12-09 15:28:09,546 basehttp "GET /favicon.ico HTTP/1.1" 404 2528
WARNING 2024-12-09 15:52:46,495 log Not Found: /storeapp/login/add_product
WARNING 2024-12-09 15:52:46,495 basehttp "GET /storeapp/login/add_product HTTP/1.1" 404 7425
WARNING 2024-12-09 15:55:50,524 log Forbidden: /storeapp/add_product/
WARNING 2024-12-09 15:55:50,525 basehttp "GET /storeapp/add_product/ HTTP/1.1" 403 318
ERROR 2024-12-09 15:56:06,769 log Internal Server Error: /storeapp/login/
Traceback (most recent call last):
  File "D:\-_SHv_4lM\Lib\site-packages\django\core\handlers\exception.py", line 55, in inner
    response = get_response(request)
               ^^^^^^^^^^^^^^^^^^^^^
  File "D:\-_SHv_4lM\Lib\site-packages\django\core\handlers\base.py", line 197, in _get_response
    response = wrapped_callback(request, *callback_args, **callback_kwargs)
               ^^^^^^^^^^^^^^^^^^^^^^^^^^^^^^^^^^^^^^^^^^^^^^^^^^^^^^^^^^^^
  File "D:\facultate\django\proiect\storeapp\views.py", line 174, in login_view
    if form.cleaned_data.get('confirmed_mail') == False:
       ^^^^^^^^^^^^^^^^^
AttributeError: 'LoginForm' object has no attribute 'cleaned_data'. Did you mean: 'changed_data'?
ERROR 2024-12-09 15:56:06,774 basehttp "POST /storeapp/login/ HTTP/1.1" 500 71985
ERROR 2024-12-09 15:57:27,558 log Internal Server Error: /storeapp/login/
Traceback (most recent call last):
  File "D:\-_SHv_4lM\Lib\site-packages\django\core\handlers\exception.py", line 55, in inner
    response = get_response(request)
               ^^^^^^^^^^^^^^^^^^^^^
  File "D:\-_SHv_4lM\Lib\site-packages\django\core\handlers\base.py", line 197, in _get_response
    response = wrapped_callback(request, *callback_args, **callback_kwargs)
               ^^^^^^^^^^^^^^^^^^^^^^^^^^^^^^^^^^^^^^^^^^^^^^^^^^^^^^^^^^^^
  File "D:\facultate\django\proiect\storeapp\views.py", line 175, in login_view
    if not user.confirmed_mail:
           ^^^^^^^^^^^^^^^^^^^
  File "D:\-_SHv_4lM\Lib\site-packages\django\utils\functional.py", line 253, in inner
    return func(_wrapped, *args)
           ^^^^^^^^^^^^^^^^^^^^^
AttributeError: 'AnonymousUser' object has no attribute 'confirmed_mail'
ERROR 2024-12-09 15:57:27,560 basehttp "POST /storeapp/login/ HTTP/1.1" 500 76295
ERROR 2024-12-09 15:57:35,759 log Internal Server Error: /storeapp/login/
Traceback (most recent call last):
  File "D:\-_SHv_4lM\Lib\site-packages\django\core\handlers\exception.py", line 55, in inner
    response = get_response(request)
               ^^^^^^^^^^^^^^^^^^^^^
  File "D:\-_SHv_4lM\Lib\site-packages\django\core\handlers\base.py", line 197, in _get_response
    response = wrapped_callback(request, *callback_args, **callback_kwargs)
               ^^^^^^^^^^^^^^^^^^^^^^^^^^^^^^^^^^^^^^^^^^^^^^^^^^^^^^^^^^^^
  File "D:\facultate\django\proiect\storeapp\views.py", line 175, in login_view
    if not user.confirmed_mail:
           ^^^^^^^^^^^^^^^^^^^
  File "D:\-_SHv_4lM\Lib\site-packages\django\utils\functional.py", line 253, in inner
    return func(_wrapped, *args)
           ^^^^^^^^^^^^^^^^^^^^^
AttributeError: 'AnonymousUser' object has no attribute 'confirmed_mail'
ERROR 2024-12-09 15:57:35,762 basehttp "POST /storeapp/login/ HTTP/1.1" 500 76295
ERROR 2024-12-09 15:58:07,195 log Internal Server Error: /storeapp/login/
Traceback (most recent call last):
  File "D:\-_SHv_4lM\Lib\site-packages\django\core\handlers\exception.py", line 55, in inner
    response = get_response(request)
               ^^^^^^^^^^^^^^^^^^^^^
  File "D:\-_SHv_4lM\Lib\site-packages\django\core\handlers\base.py", line 197, in _get_response
    response = wrapped_callback(request, *callback_args, **callback_kwargs)
               ^^^^^^^^^^^^^^^^^^^^^^^^^^^^^^^^^^^^^^^^^^^^^^^^^^^^^^^^^^^^
  File "D:\facultate\django\proiect\storeapp\views.py", line 174, in login_view
    user = CustomUser.objects.get(username=form.cleaned_data.get('username'))
                                           ^^^^^^^^^^^^^^^^^
AttributeError: 'LoginForm' object has no attribute 'cleaned_data'. Did you mean: 'changed_data'?
ERROR 2024-12-09 15:58:07,198 basehttp "POST /storeapp/login/ HTTP/1.1" 500 72089
ERROR 2024-12-09 16:00:04,346 log Internal Server Error: /storeapp/login/
Traceback (most recent call last):
  File "D:\-_SHv_4lM\Lib\site-packages\django\core\handlers\exception.py", line 55, in inner
    response = get_response(request)
               ^^^^^^^^^^^^^^^^^^^^^
  File "D:\-_SHv_4lM\Lib\site-packages\django\core\handlers\base.py", line 197, in _get_response
    response = wrapped_callback(request, *callback_args, **callback_kwargs)
               ^^^^^^^^^^^^^^^^^^^^^^^^^^^^^^^^^^^^^^^^^^^^^^^^^^^^^^^^^^^^
  File "D:\facultate\django\proiect\storeapp\views.py", line 175, in login_view
    if not user.confirmed_mail:
           ^^^^^^^^^^^^^^^^^^^
AttributeError: 'NoneType' object has no attribute 'confirmed_mail'
ERROR 2024-12-09 16:00:04,348 basehttp "POST /storeapp/login/ HTTP/1.1" 500 72142
WARNING 2024-12-09 16:03:55,687 log Forbidden: /storeapp/add_product/
WARNING 2024-12-09 16:03:55,690 basehttp "GET /storeapp/add_product/ HTTP/1.1" 403 339
WARNING 2024-12-09 16:04:36,999 log Forbidden: /storeapp/add_product/
WARNING 2024-12-09 16:04:36,999 basehttp "GET /storeapp/add_product/ HTTP/1.1" 403 725
ERROR 2024-12-09 16:13:42,552 log Internal Server Error: /storeapp/
Traceback (most recent call last):
  File "D:\-_SHv_4lM\Lib\site-packages\django\template\base.py", line 510, in parse
    compile_func = self.tags[command]
                   ~~~~~~~~~^^^^^^^^^
KeyError: 'static'

During handling of the above exception, another exception occurred:

Traceback (most recent call last):
  File "D:\-_SHv_4lM\Lib\site-packages\django\core\handlers\exception.py", line 55, in inner
    response = get_response(request)
               ^^^^^^^^^^^^^^^^^^^^^
  File "D:\-_SHv_4lM\Lib\site-packages\django\core\handlers\base.py", line 197, in _get_response
    response = wrapped_callback(request, *callback_args, **callback_kwargs)
               ^^^^^^^^^^^^^^^^^^^^^^^^^^^^^^^^^^^^^^^^^^^^^^^^^^^^^^^^^^^^
  File "D:\facultate\django\proiect\storeapp\views.py", line 21, in home
    return render(request, 'home.html')
           ^^^^^^^^^^^^^^^^^^^^^^^^^^^^
  File "D:\-_SHv_4lM\Lib\site-packages\django\shortcuts.py", line 25, in render
    content = loader.render_to_string(template_name, context, request, using=using)
              ^^^^^^^^^^^^^^^^^^^^^^^^^^^^^^^^^^^^^^^^^^^^^^^^^^^^^^^^^^^^^^^^^^^^^
  File "D:\-_SHv_4lM\Lib\site-packages\django\template\loader.py", line 61, in render_to_string
    template = get_template(template_name, using=using)
               ^^^^^^^^^^^^^^^^^^^^^^^^^^^^^^^^^^^^^^^^
  File "D:\-_SHv_4lM\Lib\site-packages\django\template\loader.py", line 15, in get_template
    return engine.get_template(template_name)
           ^^^^^^^^^^^^^^^^^^^^^^^^^^^^^^^^^^
  File "D:\-_SHv_4lM\Lib\site-packages\django\template\backends\django.py", line 79, in get_template
    return Template(self.engine.get_template(template_name), self)
                    ^^^^^^^^^^^^^^^^^^^^^^^^^^^^^^^^^^^^^^^
  File "D:\-_SHv_4lM\Lib\site-packages\django\template\engine.py", line 177, in get_template
    template, origin = self.find_template(template_name)
                       ^^^^^^^^^^^^^^^^^^^^^^^^^^^^^^^^^
  File "D:\-_SHv_4lM\Lib\site-packages\django\template\engine.py", line 159, in find_template
    template = loader.get_template(name, skip=skip)
               ^^^^^^^^^^^^^^^^^^^^^^^^^^^^^^^^^^^^
  File "D:\-_SHv_4lM\Lib\site-packages\django\template\loaders\cached.py", line 57, in get_template
    template = super().get_template(template_name, skip)
               ^^^^^^^^^^^^^^^^^^^^^^^^^^^^^^^^^^^^^^^^^
  File "D:\-_SHv_4lM\Lib\site-packages\django\template\loaders\base.py", line 28, in get_template
    return Template(
           ^^^^^^^^^
  File "D:\-_SHv_4lM\Lib\site-packages\django\template\base.py", line 154, in __init__
    self.nodelist = self.compile_nodelist()
                    ^^^^^^^^^^^^^^^^^^^^^^^
  File "D:\-_SHv_4lM\Lib\site-packages\django\template\base.py", line 196, in compile_nodelist
    nodelist = parser.parse()
               ^^^^^^^^^^^^^^
  File "D:\-_SHv_4lM\Lib\site-packages\django\template\base.py", line 512, in parse
    self.invalid_block_tag(token, command, parse_until)
  File "D:\-_SHv_4lM\Lib\site-packages\django\template\base.py", line 573, in invalid_block_tag
    raise self.error(
django.template.exceptions.TemplateSyntaxError: Invalid block tag on line 8: 'static'. Did you forget to register or load this tag?
ERROR 2024-12-09 16:13:42,560 basehttp "GET /storeapp/ HTTP/1.1" 500 146500
WARNING 2024-12-09 16:14:09,730 log Not Found: /grant-permission/
WARNING 2024-12-09 16:14:09,731 basehttp "POST /grant-permission/ HTTP/1.1" 404 2547
WARNING 2024-12-09 16:14:38,741 log Not Found: /grant-permission/
WARNING 2024-12-09 16:14:38,741 basehttp "POST /grant-permission/ HTTP/1.1" 404 2547
WARNING 2024-12-09 16:23:34,026 log Not Found: /grant_permission/
WARNING 2024-12-09 16:23:34,026 basehttp "POST /grant_permission/ HTTP/1.1" 404 2547
WARNING 2024-12-09 16:23:35,664 log Not Found: /grant_permission/
WARNING 2024-12-09 16:23:35,664 basehttp "POST /grant_permission/ HTTP/1.1" 404 2547
WARNING 2024-12-09 16:23:36,160 log Not Found: /grant_permission/
WARNING 2024-12-09 16:23:36,161 basehttp "POST /grant_permission/ HTTP/1.1" 404 2547
WARNING 2024-12-09 16:23:36,336 log Not Found: /grant_permission/
WARNING 2024-12-09 16:23:36,337 basehttp "POST /grant_permission/ HTTP/1.1" 404 2547
WARNING 2024-12-09 16:23:36,872 log Not Found: /grant_permission/
WARNING 2024-12-09 16:23:36,873 basehttp "POST /grant_permission/ HTTP/1.1" 404 2547
WARNING 2024-12-09 16:23:37,359 log Not Found: /grant_permission/
WARNING 2024-12-09 16:23:37,360 basehttp "POST /grant_permission/ HTTP/1.1" 404 2547
WARNING 2024-12-09 16:24:21,000 log Not Found: /grant_permission/
WARNING 2024-12-09 16:24:21,000 basehttp "POST /grant_permission/ HTTP/1.1" 404 2547
WARNING 2024-12-09 16:24:42,941 log Not Found: /grant_permission/
WARNING 2024-12-09 16:24:42,941 basehttp "POST /grant_permission/ HTTP/1.1" 404 2547
WARNING 2024-12-09 16:28:39,578 log Bad Request: /storeapp/grant_permission/
WARNING 2024-12-09 16:28:39,579 basehttp "POST /storeapp/grant_permission/ HTTP/1.1" 400 49
WARNING 2024-12-09 16:28:50,144 log Bad Request: /storeapp/grant_permission/
WARNING 2024-12-09 16:28:50,144 basehttp "POST /storeapp/grant_permission/ HTTP/1.1" 400 49
WARNING 2024-12-09 16:29:12,282 log Bad Request: /storeapp/grant_permission/
WARNING 2024-12-09 16:29:12,284 basehttp "POST /storeapp/grant_permission/ HTTP/1.1" 400 49
WARNING 2024-12-09 16:29:24,775 log Bad Request: /storeapp/grant_permission/
WARNING 2024-12-09 16:29:24,775 basehttp "POST /storeapp/grant_permission/ HTTP/1.1" 400 49
WARNING 2024-12-09 16:33:36,395 log Not Found: /deal/
WARNING 2024-12-09 16:33:36,396 basehttp "GET /deal/ HTTP/1.1" 404 2510
WARNING 2024-12-09 16:33:53,909 log Not Found: /deal/
WARNING 2024-12-09 16:33:53,909 basehttp "GET /deal/ HTTP/1.1" 404 2510
WARNING 2024-12-09 16:33:55,159 log Not Found: /deal/
WARNING 2024-12-09 16:33:55,159 basehttp "GET /deal/ HTTP/1.1" 404 2510
WARNING 2024-12-09 16:33:55,757 log Not Found: /deal/
WARNING 2024-12-09 16:33:55,758 basehttp "GET /deal/ HTTP/1.1" 404 2510
WARNING 2024-12-09 16:33:56,361 log Not Found: /deal/
WARNING 2024-12-09 16:33:56,361 basehttp "GET /deal/ HTTP/1.1" 404 2510
WARNING 2024-12-09 16:33:56,572 log Not Found: /deal/
WARNING 2024-12-09 16:33:56,572 basehttp "GET /deal/ HTTP/1.1" 404 2510
WARNING 2024-12-09 16:33:56,753 log Not Found: /deal/
WARNING 2024-12-09 16:33:56,754 basehttp "GET /deal/ HTTP/1.1" 404 2510
WARNING 2024-12-09 16:33:56,912 log Not Found: /deal/
WARNING 2024-12-09 16:33:56,913 basehttp "GET /deal/ HTTP/1.1" 404 2510
WARNING 2024-12-09 16:34:05,808 log Not Found: /deal/
WARNING 2024-12-09 16:34:05,809 basehttp "GET /deal/ HTTP/1.1" 404 2510
WARNING 2024-12-09 16:34:13,024 log Not Found: /deal/
WARNING 2024-12-09 16:34:13,024 basehttp "GET /deal/ HTTP/1.1" 404 2510
WARNING 2024-12-09 16:34:16,581 log Not Found: /deal/
WARNING 2024-12-09 16:34:16,582 basehttp "GET /deal/ HTTP/1.1" 404 2510
WARNING 2024-12-09 16:34:25,743 log Not Found: /deal/
WARNING 2024-12-09 16:34:25,743 basehttp "GET /deal/ HTTP/1.1" 404 2510
WARNING 2024-12-09 16:34:26,188 log Not Found: /deal/
WARNING 2024-12-09 16:34:26,188 basehttp "GET /deal/ HTTP/1.1" 404 2510
WARNING 2024-12-09 16:35:09,562 log Not Found: /deal/
WARNING 2024-12-09 16:35:09,562 basehttp "GET /deal/ HTTP/1.1" 404 2510
WARNING 2024-12-09 16:35:10,899 log Not Found: /deal/
WARNING 2024-12-09 16:35:10,900 basehttp "GET /deal/ HTTP/1.1" 404 2510
WARNING 2024-12-09 16:35:11,170 log Not Found: /deal/
WARNING 2024-12-09 16:35:11,171 basehttp "GET /deal/ HTTP/1.1" 404 2510
WARNING 2024-12-09 16:35:11,347 log Not Found: /deal/
WARNING 2024-12-09 16:35:11,348 basehttp "GET /deal/ HTTP/1.1" 404 2510
WARNING 2024-12-09 16:35:11,517 log Not Found: /deal/
WARNING 2024-12-09 16:35:11,517 basehttp "GET /deal/ HTTP/1.1" 404 2510
WARNING 2024-12-09 16:35:11,700 log Not Found: /deal/
WARNING 2024-12-09 16:35:11,701 basehttp "GET /deal/ HTTP/1.1" 404 2510
ERROR 2024-12-09 16:44:39,606 log Internal Server Error: /storeapp/logout/
Traceback (most recent call last):
  File "D:\-_SHv_4lM\Lib\site-packages\django\core\handlers\exception.py", line 55, in inner
    response = get_response(request)
               ^^^^^^^^^^^^^^^^^^^^^
  File "D:\-_SHv_4lM\Lib\site-packages\django\core\handlers\base.py", line 197, in _get_response
    response = wrapped_callback(request, *callback_args, **callback_kwargs)
               ^^^^^^^^^^^^^^^^^^^^^^^^^^^^^^^^^^^^^^^^^^^^^^^^^^^^^^^^^^^^
  File "D:\facultate\django\proiect\storeapp\views.py", line 211, in logout_view
    user = CustomUser.objects.get(username=user['username'])
                                           ~~~~^^^^^^^^^^^^
  File "D:\-_SHv_4lM\Lib\site-packages\django\utils\functional.py", line 253, in inner
    return func(_wrapped, *args)
           ^^^^^^^^^^^^^^^^^^^^^
TypeError: 'CustomUser' object is not subscriptable
ERROR 2024-12-09 16:44:39,609 basehttp "GET /storeapp/logout/ HTTP/1.1" 500 74841
ERROR 2024-12-09 16:46:18,401 log Internal Server Error: /storeapp/deal/
Traceback (most recent call last):
  File "D:\-_SHv_4lM\Lib\site-packages\django\core\handlers\exception.py", line 55, in inner
    response = get_response(request)
               ^^^^^^^^^^^^^^^^^^^^^
  File "D:\-_SHv_4lM\Lib\site-packages\django\core\handlers\base.py", line 197, in _get_response
    response = wrapped_callback(request, *callback_args, **callback_kwargs)
               ^^^^^^^^^^^^^^^^^^^^^^^^^^^^^^^^^^^^^^^^^^^^^^^^^^^^^^^^^^^^
  File "D:\facultate\django\proiect\storeapp\views.py", line 327, in deal
    random_code = register_view.generate_random_code(length=5)
                  ^^^^^^^^^^^^^^^^^^^^^^^^^^^^^^^^^^
AttributeError: 'function' object has no attribute 'generate_random_code'
ERROR 2024-12-09 16:46:18,406 basehttp "GET /storeapp/deal/ HTTP/1.1" 500 70850
ERROR 2024-12-09 16:46:44,273 log Internal Server Error: /storeapp/deal/
Traceback (most recent call last):
  File "D:\-_SHv_4lM\Lib\site-packages\django\db\backends\utils.py", line 105, in _execute
    return self.cursor.execute(sql, params)
           ^^^^^^^^^^^^^^^^^^^^^^^^^^^^^^^^
psycopg2.errors.StringDataRightTruncation: value too long for type character varying(20)


The above exception was the direct cause of the following exception:

Traceback (most recent call last):
  File "D:\-_SHv_4lM\Lib\site-packages\django\core\handlers\exception.py", line 55, in inner
    response = get_response(request)
               ^^^^^^^^^^^^^^^^^^^^^
  File "D:\-_SHv_4lM\Lib\site-packages\django\core\handlers\base.py", line 197, in _get_response
    response = wrapped_callback(request, *callback_args, **callback_kwargs)
               ^^^^^^^^^^^^^^^^^^^^^^^^^^^^^^^^^^^^^^^^^^^^^^^^^^^^^^^^^^^^
  File "D:\facultate\django\proiect\storeapp\views.py", line 328, in deal
    Discount.objects.create(code=random_code, rate=50, expiration_date=datetime.date.today() + datetime.timedelta(days=7))
  File "D:\-_SHv_4lM\Lib\site-packages\django\db\models\manager.py", line 87, in manager_method
    return getattr(self.get_queryset(), name)(*args, **kwargs)
           ^^^^^^^^^^^^^^^^^^^^^^^^^^^^^^^^^^^^^^^^^^^^^^^^^^^
  File "D:\-_SHv_4lM\Lib\site-packages\django\db\models\query.py", line 679, in create
    obj.save(force_insert=True, using=self.db)
  File "D:\-_SHv_4lM\Lib\site-packages\django\db\models\base.py", line 891, in save
    self.save_base(
  File "D:\-_SHv_4lM\Lib\site-packages\django\db\models\base.py", line 997, in save_base
    updated = self._save_table(
              ^^^^^^^^^^^^^^^^^
  File "D:\-_SHv_4lM\Lib\site-packages\django\db\models\base.py", line 1160, in _save_table
    results = self._do_insert(
              ^^^^^^^^^^^^^^^^
  File "D:\-_SHv_4lM\Lib\site-packages\django\db\models\base.py", line 1201, in _do_insert
    return manager._insert(
           ^^^^^^^^^^^^^^^^
  File "D:\-_SHv_4lM\Lib\site-packages\django\db\models\manager.py", line 87, in manager_method
    return getattr(self.get_queryset(), name)(*args, **kwargs)
           ^^^^^^^^^^^^^^^^^^^^^^^^^^^^^^^^^^^^^^^^^^^^^^^^^^^
  File "D:\-_SHv_4lM\Lib\site-packages\django\db\models\query.py", line 1847, in _insert
    return query.get_compiler(using=using).execute_sql(returning_fields)
           ^^^^^^^^^^^^^^^^^^^^^^^^^^^^^^^^^^^^^^^^^^^^^^^^^^^^^^^^^^^^^
  File "D:\-_SHv_4lM\Lib\site-packages\django\db\models\sql\compiler.py", line 1836, in execute_sql
    cursor.execute(sql, params)
  File "D:\-_SHv_4lM\Lib\site-packages\django\db\backends\utils.py", line 122, in execute
    return super().execute(sql, params)
           ^^^^^^^^^^^^^^^^^^^^^^^^^^^^
  File "D:\-_SHv_4lM\Lib\site-packages\django\db\backends\utils.py", line 79, in execute
    return self._execute_with_wrappers(
           ^^^^^^^^^^^^^^^^^^^^^^^^^^^^
  File "D:\-_SHv_4lM\Lib\site-packages\django\db\backends\utils.py", line 92, in _execute_with_wrappers
    return executor(sql, params, many, context)
           ^^^^^^^^^^^^^^^^^^^^^^^^^^^^^^^^^^^^
  File "D:\-_SHv_4lM\Lib\site-packages\django\db\backends\utils.py", line 100, in _execute
    with self.db.wrap_database_errors:
         ^^^^^^^^^^^^^^^^^^^^^^^^^^^^
  File "D:\-_SHv_4lM\Lib\site-packages\django\db\utils.py", line 91, in __exit__
    raise dj_exc_value.with_traceback(traceback) from exc_value
  File "D:\-_SHv_4lM\Lib\site-packages\django\db\backends\utils.py", line 105, in _execute
    return self.cursor.execute(sql, params)
           ^^^^^^^^^^^^^^^^^^^^^^^^^^^^^^^^
django.db.utils.DataError: value too long for type character varying(20)

ERROR 2024-12-09 16:46:44,278 basehttp "GET /storeapp/deal/ HTTP/1.1" 500 151092
ERROR 2024-12-09 16:46:45,404 log Internal Server Error: /storeapp/deal/
Traceback (most recent call last):
  File "D:\-_SHv_4lM\Lib\site-packages\django\db\backends\utils.py", line 105, in _execute
    return self.cursor.execute(sql, params)
           ^^^^^^^^^^^^^^^^^^^^^^^^^^^^^^^^
psycopg2.errors.StringDataRightTruncation: value too long for type character varying(20)


The above exception was the direct cause of the following exception:

Traceback (most recent call last):
  File "D:\-_SHv_4lM\Lib\site-packages\django\core\handlers\exception.py", line 55, in inner
    response = get_response(request)
               ^^^^^^^^^^^^^^^^^^^^^
  File "D:\-_SHv_4lM\Lib\site-packages\django\core\handlers\base.py", line 197, in _get_response
    response = wrapped_callback(request, *callback_args, **callback_kwargs)
               ^^^^^^^^^^^^^^^^^^^^^^^^^^^^^^^^^^^^^^^^^^^^^^^^^^^^^^^^^^^^
  File "D:\facultate\django\proiect\storeapp\views.py", line 328, in deal
    Discount.objects.create(code=random_code, rate=50, expiration_date=datetime.date.today() + datetime.timedelta(days=7))
  File "D:\-_SHv_4lM\Lib\site-packages\django\db\models\manager.py", line 87, in manager_method
    return getattr(self.get_queryset(), name)(*args, **kwargs)
           ^^^^^^^^^^^^^^^^^^^^^^^^^^^^^^^^^^^^^^^^^^^^^^^^^^^
  File "D:\-_SHv_4lM\Lib\site-packages\django\db\models\query.py", line 679, in create
    obj.save(force_insert=True, using=self.db)
  File "D:\-_SHv_4lM\Lib\site-packages\django\db\models\base.py", line 891, in save
    self.save_base(
  File "D:\-_SHv_4lM\Lib\site-packages\django\db\models\base.py", line 997, in save_base
    updated = self._save_table(
              ^^^^^^^^^^^^^^^^^
  File "D:\-_SHv_4lM\Lib\site-packages\django\db\models\base.py", line 1160, in _save_table
    results = self._do_insert(
              ^^^^^^^^^^^^^^^^
  File "D:\-_SHv_4lM\Lib\site-packages\django\db\models\base.py", line 1201, in _do_insert
    return manager._insert(
           ^^^^^^^^^^^^^^^^
  File "D:\-_SHv_4lM\Lib\site-packages\django\db\models\manager.py", line 87, in manager_method
    return getattr(self.get_queryset(), name)(*args, **kwargs)
           ^^^^^^^^^^^^^^^^^^^^^^^^^^^^^^^^^^^^^^^^^^^^^^^^^^^
  File "D:\-_SHv_4lM\Lib\site-packages\django\db\models\query.py", line 1847, in _insert
    return query.get_compiler(using=using).execute_sql(returning_fields)
           ^^^^^^^^^^^^^^^^^^^^^^^^^^^^^^^^^^^^^^^^^^^^^^^^^^^^^^^^^^^^^
  File "D:\-_SHv_4lM\Lib\site-packages\django\db\models\sql\compiler.py", line 1836, in execute_sql
    cursor.execute(sql, params)
  File "D:\-_SHv_4lM\Lib\site-packages\django\db\backends\utils.py", line 122, in execute
    return super().execute(sql, params)
           ^^^^^^^^^^^^^^^^^^^^^^^^^^^^
  File "D:\-_SHv_4lM\Lib\site-packages\django\db\backends\utils.py", line 79, in execute
    return self._execute_with_wrappers(
           ^^^^^^^^^^^^^^^^^^^^^^^^^^^^
  File "D:\-_SHv_4lM\Lib\site-packages\django\db\backends\utils.py", line 92, in _execute_with_wrappers
    return executor(sql, params, many, context)
           ^^^^^^^^^^^^^^^^^^^^^^^^^^^^^^^^^^^^
  File "D:\-_SHv_4lM\Lib\site-packages\django\db\backends\utils.py", line 100, in _execute
    with self.db.wrap_database_errors:
         ^^^^^^^^^^^^^^^^^^^^^^^^^^^^
  File "D:\-_SHv_4lM\Lib\site-packages\django\db\utils.py", line 91, in __exit__
    raise dj_exc_value.with_traceback(traceback) from exc_value
  File "D:\-_SHv_4lM\Lib\site-packages\django\db\backends\utils.py", line 105, in _execute
    return self.cursor.execute(sql, params)
           ^^^^^^^^^^^^^^^^^^^^^^^^^^^^^^^^
django.db.utils.DataError: value too long for type character varying(20)

ERROR 2024-12-09 16:46:45,408 basehttp "GET /storeapp/deal/ HTTP/1.1" 500 151092
ERROR 2024-12-09 16:48:14,325 log Internal Server Error: /storeapp/deal/
Traceback (most recent call last):
  File "D:\-_SHv_4lM\Lib\site-packages\django\db\backends\utils.py", line 105, in _execute
    return self.cursor.execute(sql, params)
           ^^^^^^^^^^^^^^^^^^^^^^^^^^^^^^^^
psycopg2.errors.UniqueViolation: duplicate key value violates unique constraint "storeapp_discount_pkey"
DETAIL:  Key (discount_id)=(1) already exists.


The above exception was the direct cause of the following exception:

Traceback (most recent call last):
  File "D:\-_SHv_4lM\Lib\site-packages\django\core\handlers\exception.py", line 55, in inner
    response = get_response(request)
               ^^^^^^^^^^^^^^^^^^^^^
  File "D:\-_SHv_4lM\Lib\site-packages\django\core\handlers\base.py", line 197, in _get_response
    response = wrapped_callback(request, *callback_args, **callback_kwargs)
               ^^^^^^^^^^^^^^^^^^^^^^^^^^^^^^^^^^^^^^^^^^^^^^^^^^^^^^^^^^^^
  File "D:\facultate\django\proiect\storeapp\views.py", line 329, in deal
    Discount.objects.create(code=random_code, rate=50, expiration_date=datetime.date.today() + datetime.timedelta(days=7))
  File "D:\-_SHv_4lM\Lib\site-packages\django\db\models\manager.py", line 87, in manager_method
    return getattr(self.get_queryset(), name)(*args, **kwargs)
           ^^^^^^^^^^^^^^^^^^^^^^^^^^^^^^^^^^^^^^^^^^^^^^^^^^^
  File "D:\-_SHv_4lM\Lib\site-packages\django\db\models\query.py", line 679, in create
    obj.save(force_insert=True, using=self.db)
  File "D:\-_SHv_4lM\Lib\site-packages\django\db\models\base.py", line 891, in save
    self.save_base(
  File "D:\-_SHv_4lM\Lib\site-packages\django\db\models\base.py", line 997, in save_base
    updated = self._save_table(
              ^^^^^^^^^^^^^^^^^
  File "D:\-_SHv_4lM\Lib\site-packages\django\db\models\base.py", line 1160, in _save_table
    results = self._do_insert(
              ^^^^^^^^^^^^^^^^
  File "D:\-_SHv_4lM\Lib\site-packages\django\db\models\base.py", line 1201, in _do_insert
    return manager._insert(
           ^^^^^^^^^^^^^^^^
  File "D:\-_SHv_4lM\Lib\site-packages\django\db\models\manager.py", line 87, in manager_method
    return getattr(self.get_queryset(), name)(*args, **kwargs)
           ^^^^^^^^^^^^^^^^^^^^^^^^^^^^^^^^^^^^^^^^^^^^^^^^^^^
  File "D:\-_SHv_4lM\Lib\site-packages\django\db\models\query.py", line 1847, in _insert
    return query.get_compiler(using=using).execute_sql(returning_fields)
           ^^^^^^^^^^^^^^^^^^^^^^^^^^^^^^^^^^^^^^^^^^^^^^^^^^^^^^^^^^^^^
  File "D:\-_SHv_4lM\Lib\site-packages\django\db\models\sql\compiler.py", line 1836, in execute_sql
    cursor.execute(sql, params)
  File "D:\-_SHv_4lM\Lib\site-packages\django\db\backends\utils.py", line 122, in execute
    return super().execute(sql, params)
           ^^^^^^^^^^^^^^^^^^^^^^^^^^^^
  File "D:\-_SHv_4lM\Lib\site-packages\django\db\backends\utils.py", line 79, in execute
    return self._execute_with_wrappers(
           ^^^^^^^^^^^^^^^^^^^^^^^^^^^^
  File "D:\-_SHv_4lM\Lib\site-packages\django\db\backends\utils.py", line 92, in _execute_with_wrappers
    return executor(sql, params, many, context)
           ^^^^^^^^^^^^^^^^^^^^^^^^^^^^^^^^^^^^
  File "D:\-_SHv_4lM\Lib\site-packages\django\db\backends\utils.py", line 100, in _execute
    with self.db.wrap_database_errors:
         ^^^^^^^^^^^^^^^^^^^^^^^^^^^^
  File "D:\-_SHv_4lM\Lib\site-packages\django\db\utils.py", line 91, in __exit__
    raise dj_exc_value.with_traceback(traceback) from exc_value
  File "D:\-_SHv_4lM\Lib\site-packages\django\db\backends\utils.py", line 105, in _execute
    return self.cursor.execute(sql, params)
           ^^^^^^^^^^^^^^^^^^^^^^^^^^^^^^^^
django.db.utils.IntegrityError: duplicate key value violates unique constraint "storeapp_discount_pkey"
DETAIL:  Key (discount_id)=(1) already exists.

ERROR 2024-12-09 16:48:14,330 basehttp "GET /storeapp/deal/ HTTP/1.1" 500 150634
ERROR 2024-12-09 16:49:17,036 log Internal Server Error: /storeapp/deal/
Traceback (most recent call last):
  File "D:\-_SHv_4lM\Lib\site-packages\django\db\backends\utils.py", line 105, in _execute
    return self.cursor.execute(sql, params)
           ^^^^^^^^^^^^^^^^^^^^^^^^^^^^^^^^
psycopg2.errors.UniqueViolation: duplicate key value violates unique constraint "storeapp_discount_pkey"
DETAIL:  Key (discount_id)=(2) already exists.


The above exception was the direct cause of the following exception:

Traceback (most recent call last):
  File "D:\-_SHv_4lM\Lib\site-packages\django\core\handlers\exception.py", line 55, in inner
    response = get_response(request)
               ^^^^^^^^^^^^^^^^^^^^^
  File "D:\-_SHv_4lM\Lib\site-packages\django\core\handlers\base.py", line 197, in _get_response
    response = wrapped_callback(request, *callback_args, **callback_kwargs)
               ^^^^^^^^^^^^^^^^^^^^^^^^^^^^^^^^^^^^^^^^^^^^^^^^^^^^^^^^^^^^
  File "D:\facultate\django\proiect\storeapp\views.py", line 329, in deal
    Discount.objects.create(code=random_code, rate=50, expiration_date=datetime.date.today() + datetime.timedelta(days=7))
  File "D:\-_SHv_4lM\Lib\site-packages\django\db\models\manager.py", line 87, in manager_method
    return getattr(self.get_queryset(), name)(*args, **kwargs)
           ^^^^^^^^^^^^^^^^^^^^^^^^^^^^^^^^^^^^^^^^^^^^^^^^^^^
  File "D:\-_SHv_4lM\Lib\site-packages\django\db\models\query.py", line 679, in create
    obj.save(force_insert=True, using=self.db)
  File "D:\-_SHv_4lM\Lib\site-packages\django\db\models\base.py", line 891, in save
    self.save_base(
  File "D:\-_SHv_4lM\Lib\site-packages\django\db\models\base.py", line 997, in save_base
    updated = self._save_table(
              ^^^^^^^^^^^^^^^^^
  File "D:\-_SHv_4lM\Lib\site-packages\django\db\models\base.py", line 1160, in _save_table
    results = self._do_insert(
              ^^^^^^^^^^^^^^^^
  File "D:\-_SHv_4lM\Lib\site-packages\django\db\models\base.py", line 1201, in _do_insert
    return manager._insert(
           ^^^^^^^^^^^^^^^^
  File "D:\-_SHv_4lM\Lib\site-packages\django\db\models\manager.py", line 87, in manager_method
    return getattr(self.get_queryset(), name)(*args, **kwargs)
           ^^^^^^^^^^^^^^^^^^^^^^^^^^^^^^^^^^^^^^^^^^^^^^^^^^^
  File "D:\-_SHv_4lM\Lib\site-packages\django\db\models\query.py", line 1847, in _insert
    return query.get_compiler(using=using).execute_sql(returning_fields)
           ^^^^^^^^^^^^^^^^^^^^^^^^^^^^^^^^^^^^^^^^^^^^^^^^^^^^^^^^^^^^^
  File "D:\-_SHv_4lM\Lib\site-packages\django\db\models\sql\compiler.py", line 1836, in execute_sql
    cursor.execute(sql, params)
  File "D:\-_SHv_4lM\Lib\site-packages\django\db\backends\utils.py", line 122, in execute
    return super().execute(sql, params)
           ^^^^^^^^^^^^^^^^^^^^^^^^^^^^
  File "D:\-_SHv_4lM\Lib\site-packages\django\db\backends\utils.py", line 79, in execute
    return self._execute_with_wrappers(
           ^^^^^^^^^^^^^^^^^^^^^^^^^^^^
  File "D:\-_SHv_4lM\Lib\site-packages\django\db\backends\utils.py", line 92, in _execute_with_wrappers
    return executor(sql, params, many, context)
           ^^^^^^^^^^^^^^^^^^^^^^^^^^^^^^^^^^^^
  File "D:\-_SHv_4lM\Lib\site-packages\django\db\backends\utils.py", line 100, in _execute
    with self.db.wrap_database_errors:
         ^^^^^^^^^^^^^^^^^^^^^^^^^^^^
  File "D:\-_SHv_4lM\Lib\site-packages\django\db\utils.py", line 91, in __exit__
    raise dj_exc_value.with_traceback(traceback) from exc_value
  File "D:\-_SHv_4lM\Lib\site-packages\django\db\backends\utils.py", line 105, in _execute
    return self.cursor.execute(sql, params)
           ^^^^^^^^^^^^^^^^^^^^^^^^^^^^^^^^
django.db.utils.IntegrityError: duplicate key value violates unique constraint "storeapp_discount_pkey"
DETAIL:  Key (discount_id)=(2) already exists.

ERROR 2024-12-09 16:49:17,041 basehttp "GET /storeapp/deal/ HTTP/1.1" 500 150634
WARNING 2024-12-09 16:51:22,312 log Forbidden: /storeapp/deal/
WARNING 2024-12-09 16:51:22,312 basehttp "GET /storeapp/deal/ HTTP/1.1" 403 728
WARNING 2024-12-09 16:51:46,309 log Forbidden: /storeapp/deal/
WARNING 2024-12-09 16:51:46,309 basehttp "GET /storeapp/deal/ HTTP/1.1" 403 720
WARNING 2024-12-10 13:48:12,697 log Not Found: /
WARNING 2024-12-10 13:48:12,698 basehttp "GET / HTTP/1.1" 404 2477
WARNING 2024-12-10 13:48:12,764 log Not Found: /favicon.ico
WARNING 2024-12-10 13:48:12,764 basehttp "GET /favicon.ico HTTP/1.1" 404 2528
WARNING 2024-12-10 14:06:16,766 log Bad Request: /storeapp/grant_permission/
WARNING 2024-12-10 14:06:16,766 basehttp "POST /storeapp/grant_permission/ HTTP/1.1" 400 72
WARNING 2024-12-10 14:06:53,366 log Bad Request: /storeapp/grant_permission/
WARNING 2024-12-10 14:06:53,366 basehttp "POST /storeapp/grant_permission/ HTTP/1.1" 400 72
WARNING 2024-12-10 14:11:40,235 log Not Found: /storeapp/products/{% url 'display_product' product.product_id     %}
WARNING 2024-12-10 14:11:40,237 basehttp "GET /storeapp/products/%7B%%20url%20'display_product'%20product.product_id%20%20%20%20%20%%7D HTTP/1.1" 404 8149
WARNING 2024-12-10 14:12:19,645 log Not Found: /storeapp/products/{% url 'display_product' product.product_id     %}
WARNING 2024-12-10 14:12:19,645 basehttp "GET /storeapp/products/%7B%%20url%20'display_product'%20product.product_id%20%20%20%20%20%%7D HTTP/1.1" 404 8149
WARNING 2024-12-10 14:14:49,338 log Not Found: /storeapp/products/{% url 'display_product' product.product_id     %}
WARNING 2024-12-10 14:14:49,338 basehttp "GET /storeapp/products/%7B%%20url%20'display_product'%20product.product_id%20%20%20%20%20%%7D HTTP/1.1" 404 8149
WARNING 2024-12-10 14:14:51,041 log Not Found: /storeapp/products/{% url 'display_product' product.product_id     %}
WARNING 2024-12-10 14:14:51,042 basehttp "GET /storeapp/products/%7B%%20url%20'display_product'%20product.product_id%20%20%20%20%20%%7D HTTP/1.1" 404 8149
WARNING 2024-12-10 14:16:46,114 log Not Found: /storeapp/products/{% url 'display_product' product.product_id     %}
WARNING 2024-12-10 14:16:46,114 basehttp "GET /storeapp/products/%7B%%20url%20'display_product'%20product.product_id%20%20%20%20%20%%7D HTTP/1.1" 404 8149
WARNING 2024-12-10 14:17:01,959 log Not Found: /storeapp/products/{% url 'display_product' product.product_id     %}
WARNING 2024-12-10 14:17:01,959 basehttp "GET /storeapp/products/%7B%%20url%20'display_product'%20product.product_id%20%20%20%20%20%%7D HTTP/1.1" 404 8149
WARNING 2024-12-10 14:17:02,542 log Not Found: /storeapp/products/{% url 'display_product' product.product_id     %}
WARNING 2024-12-10 14:17:02,542 basehttp "GET /storeapp/products/%7B%%20url%20'display_product'%20product.product_id%20%20%20%20%20%%7D HTTP/1.1" 404 8149
WARNING 2024-12-10 14:17:02,855 log Not Found: /storeapp/products/{% url 'display_product' product.product_id     %}
WARNING 2024-12-10 14:17:02,856 basehttp "GET /storeapp/products/%7B%%20url%20'display_product'%20product.product_id%20%20%20%20%20%%7D HTTP/1.1" 404 8149
WARNING 2024-12-10 14:17:03,044 log Not Found: /storeapp/products/{% url 'display_product' product.product_id     %}
WARNING 2024-12-10 14:17:03,044 basehttp "GET /storeapp/products/%7B%%20url%20'display_product'%20product.product_id%20%20%20%20%20%%7D HTTP/1.1" 404 8149
WARNING 2024-12-10 14:17:03,264 log Not Found: /storeapp/products/{% url 'display_product' product.product_id     %}
WARNING 2024-12-10 14:17:03,264 basehttp "GET /storeapp/products/%7B%%20url%20'display_product'%20product.product_id%20%20%20%20%20%%7D HTTP/1.1" 404 8149
WARNING 2024-12-10 14:17:03,464 log Not Found: /storeapp/products/{% url 'display_product' product.product_id     %}
WARNING 2024-12-10 14:17:03,464 basehttp "GET /storeapp/products/%7B%%20url%20'display_product'%20product.product_id%20%20%20%20%20%%7D HTTP/1.1" 404 8149
WARNING 2024-12-10 14:17:03,653 log Not Found: /storeapp/products/{% url 'display_product' product.product_id     %}
WARNING 2024-12-10 14:17:03,654 basehttp "GET /storeapp/products/%7B%%20url%20'display_product'%20product.product_id%20%20%20%20%20%%7D HTTP/1.1" 404 8149
WARNING 2024-12-10 14:17:10,940 log Not Found: /storeapp/products/{% url 'display_product' product.product_id     %}
WARNING 2024-12-10 14:17:10,942 basehttp "GET /storeapp/products/%7B%%20url%20'display_product'%20product.product_id%20%20%20%20%20%%7D HTTP/1.1" 404 8149
WARNING 2024-12-10 14:17:40,353 log Not Found: /storeapp/products/{% url 'display_product' product.product_id     %}
WARNING 2024-12-10 14:17:40,353 basehttp "GET /storeapp/products/%7B%%20url%20'display_product'%20product.product_id%20%20%20%20%20%%7D HTTP/1.1" 404 8149
WARNING 2024-12-10 14:17:45,371 log Not Found: /storeapp/products/{% url 'display_product' product.product_id     %}
WARNING 2024-12-10 14:17:45,372 basehttp "GET /storeapp/products/%7B%%20url%20'display_product'%20product.product_id%20%20%20%20%20%%7D HTTP/1.1" 404 8149
WARNING 2024-12-10 14:18:06,080 log Not Found: /storeapp/products/{% url 'display_product' product.product_id     %}
WARNING 2024-12-10 14:18:06,080 basehttp "GET /storeapp/products/%7B%%20url%20'display_product'%20product.product_id%20%20%20%20%20%%7D HTTP/1.1" 404 8149
WARNING 2024-12-10 14:18:12,631 log Not Found: /storeapp/products/{% url 'display_product' product.product_id     %}
WARNING 2024-12-10 14:18:12,631 basehttp "GET /storeapp/products/%7B%%20url%20'display_product'%20product.product_id%20%20%20%20%20%%7D HTTP/1.1" 404 8149
WARNING 2024-12-10 14:18:46,884 log Not Found: /favicon.ico
WARNING 2024-12-10 14:18:46,885 basehttp "GET /favicon.ico HTTP/1.1" 404 2528
WARNING 2024-12-10 18:16:54,632 log Not Found: /
WARNING 2024-12-10 18:16:54,633 basehttp "GET / HTTP/1.1" 404 2477
WARNING 2024-12-10 18:16:54,715 log Not Found: /favicon.ico
WARNING 2024-12-10 18:16:54,715 basehttp "GET /favicon.ico HTTP/1.1" 404 2528
WARNING 2024-12-10 19:23:39,620 log Not Found: /favicon.ico
WARNING 2024-12-10 19:23:39,620 basehttp "GET /favicon.ico HTTP/1.1" 404 2528
WARNING 2024-12-10 19:23:55,440 log Forbidden (CSRF token from POST incorrect.): /storeapp/login/
WARNING 2024-12-10 19:23:55,440 basehttp "POST /storeapp/login/ HTTP/1.1" 403 2503
WARNING 2024-12-12 13:13:40,819 log Not Found: /
WARNING 2024-12-12 13:13:40,821 basehttp "GET / HTTP/1.1" 404 2477
WARNING 2024-12-12 13:13:40,932 log Not Found: /favicon.ico
WARNING 2024-12-12 13:13:40,933 basehttp "GET /favicon.ico HTTP/1.1" 404 2528
WARNING 2024-12-12 14:01:31,293 log Bad Request: /storeapp/checkout/
WARNING 2024-12-12 14:01:31,294 basehttp "GET /storeapp/checkout/ HTTP/1.1" 400 49
WARNING 2024-12-12 14:02:41,843 log Bad Request: /storeapp/checkout/
WARNING 2024-12-12 14:02:41,843 basehttp "GET /storeapp/checkout/ HTTP/1.1" 400 49
WARNING 2024-12-12 14:02:42,405 log Bad Request: /storeapp/checkout/
WARNING 2024-12-12 14:02:42,405 basehttp "GET /storeapp/checkout/ HTTP/1.1" 400 49
WARNING 2024-12-12 14:03:58,453 log Bad Request: /storeapp/checkout/
WARNING 2024-12-12 14:03:58,454 basehttp "GET /storeapp/checkout/ HTTP/1.1" 400 49
WARNING 2024-12-12 14:04:00,972 log Bad Request: /storeapp/checkout/
WARNING 2024-12-12 14:04:00,973 basehttp "GET /storeapp/checkout/ HTTP/1.1" 400 49
WARNING 2024-12-12 14:05:53,636 log Bad Request: /storeapp/checkout/
WARNING 2024-12-12 14:05:53,636 basehttp "GET /storeapp/checkout/ HTTP/1.1" 400 49
WARNING 2024-12-12 14:07:11,309 log Bad Request: /storeapp/checkout/
WARNING 2024-12-12 14:07:11,310 basehttp "GET /storeapp/checkout/ HTTP/1.1" 400 49
WARNING 2024-12-12 14:07:16,664 log Bad Request: /storeapp/checkout/
WARNING 2024-12-12 14:07:16,664 basehttp "GET /storeapp/checkout/ HTTP/1.1" 400 49
WARNING 2024-12-12 14:07:31,593 log Bad Request: /storeapp/checkout/
WARNING 2024-12-12 14:07:31,597 basehttp "GET /storeapp/checkout/ HTTP/1.1" 400 49
WARNING 2024-12-12 14:07:37,308 log Bad Request: /storeapp/checkout/
WARNING 2024-12-12 14:07:37,309 basehttp "GET /storeapp/checkout/ HTTP/1.1" 400 49
WARNING 2024-12-12 14:08:13,767 log Bad Request: /storeapp/checkout/
WARNING 2024-12-12 14:08:13,768 basehttp "GET /storeapp/checkout/ HTTP/1.1" 400 49
WARNING 2024-12-12 14:08:57,621 log Not Found: /storeapp/checkout/
WARNING 2024-12-12 14:08:57,622 basehttp "GET /storeapp/checkout/ HTTP/1.1" 404 8504
WARNING 2024-12-12 14:09:11,615 log Bad Request: /storeapp/cart/
WARNING 2024-12-12 14:09:11,615 basehttp "GET /storeapp/cart/ HTTP/1.1" 400 49
WARNING 2024-12-12 14:11:34,662 log Bad Request: /storeapp/cart/
WARNING 2024-12-12 14:11:34,664 basehttp "GET /storeapp/cart/ HTTP/1.1" 400 56
WARNING 2024-12-12 14:11:35,273 log Bad Request: /storeapp/cart/
WARNING 2024-12-12 14:11:35,273 basehttp "GET /storeapp/cart/ HTTP/1.1" 400 56
WARNING 2024-12-12 14:11:35,809 log Bad Request: /storeapp/cart/
WARNING 2024-12-12 14:11:35,809 basehttp "GET /storeapp/cart/ HTTP/1.1" 400 56
WARNING 2024-12-12 14:13:44,054 log Bad Request: /storeapp/cart/
WARNING 2024-12-12 14:13:44,055 basehttp "GET /storeapp/cart/ HTTP/1.1" 400 56
WARNING 2024-12-12 14:13:44,945 log Bad Request: /storeapp/cart/
WARNING 2024-12-12 14:13:44,946 basehttp "GET /storeapp/cart/ HTTP/1.1" 400 56
WARNING 2024-12-12 14:13:48,307 log Bad Request: /storeapp/cart/
WARNING 2024-12-12 14:13:48,307 basehttp "GET /storeapp/cart/ HTTP/1.1" 400 56
ERROR 2024-12-12 14:14:16,821 log Internal Server Error: /storeapp/cart/
Traceback (most recent call last):
  File "D:\-_SHv_4lM\Lib\site-packages\django\core\handlers\exception.py", line 55, in inner
    response = get_response(request)
               ^^^^^^^^^^^^^^^^^^^^^
  File "D:\-_SHv_4lM\Lib\site-packages\django\core\handlers\base.py", line 204, in _get_response
    self.check_response(response, callback)
  File "D:\-_SHv_4lM\Lib\site-packages\django\core\handlers\base.py", line 332, in check_response
    raise ValueError(
ValueError: The view storeapp.views.cart didn't return an HttpResponse object. It returned None instead.
ERROR 2024-12-12 14:14:16,823 basehttp "GET /storeapp/cart/ HTTP/1.1" 500 72093
ERROR 2024-12-12 14:15:36,284 log Internal Server Error: /storeapp/cart/
Traceback (most recent call last):
  File "D:\-_SHv_4lM\Lib\site-packages\django\core\handlers\exception.py", line 55, in inner
    response = get_response(request)
               ^^^^^^^^^^^^^^^^^^^^^
  File "D:\-_SHv_4lM\Lib\site-packages\django\core\handlers\base.py", line 204, in _get_response
    self.check_response(response, callback)
  File "D:\-_SHv_4lM\Lib\site-packages\django\core\handlers\base.py", line 332, in check_response
    raise ValueError(
ValueError: The view storeapp.views.cart didn't return an HttpResponse object. It returned None instead.
ERROR 2024-12-12 14:15:36,287 basehttp "GET /storeapp/cart/ HTTP/1.1" 500 72230
ERROR 2024-12-12 14:15:36,935 log Internal Server Error: /storeapp/cart/
Traceback (most recent call last):
  File "D:\-_SHv_4lM\Lib\site-packages\django\core\handlers\exception.py", line 55, in inner
    response = get_response(request)
               ^^^^^^^^^^^^^^^^^^^^^
  File "D:\-_SHv_4lM\Lib\site-packages\django\core\handlers\base.py", line 204, in _get_response
    self.check_response(response, callback)
  File "D:\-_SHv_4lM\Lib\site-packages\django\core\handlers\base.py", line 332, in check_response
    raise ValueError(
ValueError: The view storeapp.views.cart didn't return an HttpResponse object. It returned None instead.
ERROR 2024-12-12 14:15:36,937 basehttp "GET /storeapp/cart/ HTTP/1.1" 500 72230
ERROR 2024-12-12 14:15:37,416 log Internal Server Error: /storeapp/cart/
Traceback (most recent call last):
  File "D:\-_SHv_4lM\Lib\site-packages\django\core\handlers\exception.py", line 55, in inner
    response = get_response(request)
               ^^^^^^^^^^^^^^^^^^^^^
  File "D:\-_SHv_4lM\Lib\site-packages\django\core\handlers\base.py", line 204, in _get_response
    self.check_response(response, callback)
  File "D:\-_SHv_4lM\Lib\site-packages\django\core\handlers\base.py", line 332, in check_response
    raise ValueError(
ValueError: The view storeapp.views.cart didn't return an HttpResponse object. It returned None instead.
ERROR 2024-12-12 14:15:37,418 basehttp "GET /storeapp/cart/ HTTP/1.1" 500 72230
ERROR 2024-12-12 14:15:37,733 log Internal Server Error: /storeapp/cart/
Traceback (most recent call last):
  File "D:\-_SHv_4lM\Lib\site-packages\django\core\handlers\exception.py", line 55, in inner
    response = get_response(request)
               ^^^^^^^^^^^^^^^^^^^^^
  File "D:\-_SHv_4lM\Lib\site-packages\django\core\handlers\base.py", line 204, in _get_response
    self.check_response(response, callback)
  File "D:\-_SHv_4lM\Lib\site-packages\django\core\handlers\base.py", line 332, in check_response
    raise ValueError(
ValueError: The view storeapp.views.cart didn't return an HttpResponse object. It returned None instead.
ERROR 2024-12-12 14:15:37,737 basehttp "GET /storeapp/cart/ HTTP/1.1" 500 72230
ERROR 2024-12-12 14:15:38,058 log Internal Server Error: /storeapp/cart/
Traceback (most recent call last):
  File "D:\-_SHv_4lM\Lib\site-packages\django\core\handlers\exception.py", line 55, in inner
    response = get_response(request)
               ^^^^^^^^^^^^^^^^^^^^^
  File "D:\-_SHv_4lM\Lib\site-packages\django\core\handlers\base.py", line 204, in _get_response
    self.check_response(response, callback)
  File "D:\-_SHv_4lM\Lib\site-packages\django\core\handlers\base.py", line 332, in check_response
    raise ValueError(
ValueError: The view storeapp.views.cart didn't return an HttpResponse object. It returned None instead.
ERROR 2024-12-12 14:15:38,060 basehttp "GET /storeapp/cart/ HTTP/1.1" 500 72230
ERROR 2024-12-12 14:15:38,160 log Internal Server Error: /storeapp/cart/
Traceback (most recent call last):
  File "D:\-_SHv_4lM\Lib\site-packages\django\core\handlers\exception.py", line 55, in inner
    response = get_response(request)
               ^^^^^^^^^^^^^^^^^^^^^
  File "D:\-_SHv_4lM\Lib\site-packages\django\core\handlers\base.py", line 204, in _get_response
    self.check_response(response, callback)
  File "D:\-_SHv_4lM\Lib\site-packages\django\core\handlers\base.py", line 332, in check_response
    raise ValueError(
ValueError: The view storeapp.views.cart didn't return an HttpResponse object. It returned None instead.
ERROR 2024-12-12 14:15:38,163 basehttp "GET /storeapp/cart/ HTTP/1.1" 500 72230
ERROR 2024-12-12 14:15:38,340 log Internal Server Error: /storeapp/cart/
Traceback (most recent call last):
  File "D:\-_SHv_4lM\Lib\site-packages\django\core\handlers\exception.py", line 55, in inner
    response = get_response(request)
               ^^^^^^^^^^^^^^^^^^^^^
  File "D:\-_SHv_4lM\Lib\site-packages\django\core\handlers\base.py", line 204, in _get_response
    self.check_response(response, callback)
  File "D:\-_SHv_4lM\Lib\site-packages\django\core\handlers\base.py", line 332, in check_response
    raise ValueError(
ValueError: The view storeapp.views.cart didn't return an HttpResponse object. It returned None instead.
ERROR 2024-12-12 14:15:38,344 basehttp "GET /storeapp/cart/ HTTP/1.1" 500 72230
ERROR 2024-12-12 14:15:41,999 log Internal Server Error: /storeapp/cart/
Traceback (most recent call last):
  File "D:\-_SHv_4lM\Lib\site-packages\django\core\handlers\exception.py", line 55, in inner
    response = get_response(request)
               ^^^^^^^^^^^^^^^^^^^^^
  File "D:\-_SHv_4lM\Lib\site-packages\django\core\handlers\base.py", line 204, in _get_response
    self.check_response(response, callback)
  File "D:\-_SHv_4lM\Lib\site-packages\django\core\handlers\base.py", line 332, in check_response
    raise ValueError(
ValueError: The view storeapp.views.cart didn't return an HttpResponse object. It returned None instead.
ERROR 2024-12-12 14:15:42,003 basehttp "GET /storeapp/cart/ HTTP/1.1" 500 72093
ERROR 2024-12-12 14:16:33,902 log Internal Server Error: /storeapp/cart/
Traceback (most recent call last):
  File "D:\-_SHv_4lM\Lib\site-packages\django\core\handlers\exception.py", line 55, in inner
    response = get_response(request)
               ^^^^^^^^^^^^^^^^^^^^^
  File "D:\-_SHv_4lM\Lib\site-packages\django\core\handlers\base.py", line 204, in _get_response
    self.check_response(response, callback)
  File "D:\-_SHv_4lM\Lib\site-packages\django\core\handlers\base.py", line 332, in check_response
    raise ValueError(
ValueError: The view storeapp.views.cart didn't return an HttpResponse object. It returned None instead.
ERROR 2024-12-12 14:16:33,911 basehttp "GET /storeapp/cart/ HTTP/1.1" 500 72230
ERROR 2024-12-12 14:16:34,883 log Internal Server Error: /storeapp/cart/
Traceback (most recent call last):
  File "D:\-_SHv_4lM\Lib\site-packages\django\core\handlers\exception.py", line 55, in inner
    response = get_response(request)
               ^^^^^^^^^^^^^^^^^^^^^
  File "D:\-_SHv_4lM\Lib\site-packages\django\core\handlers\base.py", line 204, in _get_response
    self.check_response(response, callback)
  File "D:\-_SHv_4lM\Lib\site-packages\django\core\handlers\base.py", line 332, in check_response
    raise ValueError(
ValueError: The view storeapp.views.cart didn't return an HttpResponse object. It returned None instead.
ERROR 2024-12-12 14:16:34,885 basehttp "GET /storeapp/cart/ HTTP/1.1" 500 72230
ERROR 2024-12-12 14:16:35,266 log Internal Server Error: /storeapp/cart/
Traceback (most recent call last):
  File "D:\-_SHv_4lM\Lib\site-packages\django\core\handlers\exception.py", line 55, in inner
    response = get_response(request)
               ^^^^^^^^^^^^^^^^^^^^^
  File "D:\-_SHv_4lM\Lib\site-packages\django\core\handlers\base.py", line 204, in _get_response
    self.check_response(response, callback)
  File "D:\-_SHv_4lM\Lib\site-packages\django\core\handlers\base.py", line 332, in check_response
    raise ValueError(
ValueError: The view storeapp.views.cart didn't return an HttpResponse object. It returned None instead.
ERROR 2024-12-12 14:16:35,268 basehttp "GET /storeapp/cart/ HTTP/1.1" 500 72230
ERROR 2024-12-12 14:16:35,562 log Internal Server Error: /storeapp/cart/
Traceback (most recent call last):
  File "D:\-_SHv_4lM\Lib\site-packages\django\core\handlers\exception.py", line 55, in inner
    response = get_response(request)
               ^^^^^^^^^^^^^^^^^^^^^
  File "D:\-_SHv_4lM\Lib\site-packages\django\core\handlers\base.py", line 204, in _get_response
    self.check_response(response, callback)
  File "D:\-_SHv_4lM\Lib\site-packages\django\core\handlers\base.py", line 332, in check_response
    raise ValueError(
ValueError: The view storeapp.views.cart didn't return an HttpResponse object. It returned None instead.
ERROR 2024-12-12 14:16:35,565 basehttp "GET /storeapp/cart/ HTTP/1.1" 500 72230
ERROR 2024-12-12 14:16:35,846 log Internal Server Error: /storeapp/cart/
Traceback (most recent call last):
  File "D:\-_SHv_4lM\Lib\site-packages\django\core\handlers\exception.py", line 55, in inner
    response = get_response(request)
               ^^^^^^^^^^^^^^^^^^^^^
  File "D:\-_SHv_4lM\Lib\site-packages\django\core\handlers\base.py", line 204, in _get_response
    self.check_response(response, callback)
  File "D:\-_SHv_4lM\Lib\site-packages\django\core\handlers\base.py", line 332, in check_response
    raise ValueError(
ValueError: The view storeapp.views.cart didn't return an HttpResponse object. It returned None instead.
ERROR 2024-12-12 14:16:35,848 basehttp "GET /storeapp/cart/ HTTP/1.1" 500 72230
ERROR 2024-12-12 14:16:36,068 log Internal Server Error: /storeapp/cart/
Traceback (most recent call last):
  File "D:\-_SHv_4lM\Lib\site-packages\django\core\handlers\exception.py", line 55, in inner
    response = get_response(request)
               ^^^^^^^^^^^^^^^^^^^^^
  File "D:\-_SHv_4lM\Lib\site-packages\django\core\handlers\base.py", line 204, in _get_response
    self.check_response(response, callback)
  File "D:\-_SHv_4lM\Lib\site-packages\django\core\handlers\base.py", line 332, in check_response
    raise ValueError(
ValueError: The view storeapp.views.cart didn't return an HttpResponse object. It returned None instead.
ERROR 2024-12-12 14:16:36,071 basehttp "GET /storeapp/cart/ HTTP/1.1" 500 72230
ERROR 2024-12-12 14:16:36,217 log Internal Server Error: /storeapp/cart/
Traceback (most recent call last):
  File "D:\-_SHv_4lM\Lib\site-packages\django\core\handlers\exception.py", line 55, in inner
    response = get_response(request)
               ^^^^^^^^^^^^^^^^^^^^^
  File "D:\-_SHv_4lM\Lib\site-packages\django\core\handlers\base.py", line 204, in _get_response
    self.check_response(response, callback)
  File "D:\-_SHv_4lM\Lib\site-packages\django\core\handlers\base.py", line 332, in check_response
    raise ValueError(
ValueError: The view storeapp.views.cart didn't return an HttpResponse object. It returned None instead.
ERROR 2024-12-12 14:16:36,219 basehttp "GET /storeapp/cart/ HTTP/1.1" 500 72230
ERROR 2024-12-12 14:16:36,385 log Internal Server Error: /storeapp/cart/
Traceback (most recent call last):
  File "D:\-_SHv_4lM\Lib\site-packages\django\core\handlers\exception.py", line 55, in inner
    response = get_response(request)
               ^^^^^^^^^^^^^^^^^^^^^
  File "D:\-_SHv_4lM\Lib\site-packages\django\core\handlers\base.py", line 204, in _get_response
    self.check_response(response, callback)
  File "D:\-_SHv_4lM\Lib\site-packages\django\core\handlers\base.py", line 332, in check_response
    raise ValueError(
ValueError: The view storeapp.views.cart didn't return an HttpResponse object. It returned None instead.
ERROR 2024-12-12 14:16:36,388 basehttp "GET /storeapp/cart/ HTTP/1.1" 500 72230
ERROR 2024-12-12 14:16:36,534 log Internal Server Error: /storeapp/cart/
Traceback (most recent call last):
  File "D:\-_SHv_4lM\Lib\site-packages\django\core\handlers\exception.py", line 55, in inner
    response = get_response(request)
               ^^^^^^^^^^^^^^^^^^^^^
  File "D:\-_SHv_4lM\Lib\site-packages\django\core\handlers\base.py", line 204, in _get_response
    self.check_response(response, callback)
  File "D:\-_SHv_4lM\Lib\site-packages\django\core\handlers\base.py", line 332, in check_response
    raise ValueError(
ValueError: The view storeapp.views.cart didn't return an HttpResponse object. It returned None instead.
ERROR 2024-12-12 14:16:36,537 basehttp "GET /storeapp/cart/ HTTP/1.1" 500 72230
ERROR 2024-12-12 14:16:54,246 log Internal Server Error: /storeapp/cart/
Traceback (most recent call last):
  File "D:\-_SHv_4lM\Lib\site-packages\django\template\base.py", line 510, in parse
    compile_func = self.tags[command]
                   ~~~~~~~~~^^^^^^^^^
KeyError: 'static'

During handling of the above exception, another exception occurred:

Traceback (most recent call last):
  File "D:\-_SHv_4lM\Lib\site-packages\django\core\handlers\exception.py", line 55, in inner
    response = get_response(request)
               ^^^^^^^^^^^^^^^^^^^^^
  File "D:\-_SHv_4lM\Lib\site-packages\django\core\handlers\base.py", line 197, in _get_response
    response = wrapped_callback(request, *callback_args, **callback_kwargs)
               ^^^^^^^^^^^^^^^^^^^^^^^^^^^^^^^^^^^^^^^^^^^^^^^^^^^^^^^^^^^^
  File "D:\-_SHv_4lM\Lib\site-packages\django\views\decorators\csrf.py", line 65, in _view_wrapper
    return view_func(request, *args, **kwargs)
           ^^^^^^^^^^^^^^^^^^^^^^^^^^^^^^^^^^^
  File "D:\facultate\django\proiect\storeapp\views.py", line 348, in cart
    return render(request, 'cart.html')
           ^^^^^^^^^^^^^^^^^^^^^^^^^^^^
  File "D:\-_SHv_4lM\Lib\site-packages\django\shortcuts.py", line 25, in render
    content = loader.render_to_string(template_name, context, request, using=using)
              ^^^^^^^^^^^^^^^^^^^^^^^^^^^^^^^^^^^^^^^^^^^^^^^^^^^^^^^^^^^^^^^^^^^^^
  File "D:\-_SHv_4lM\Lib\site-packages\django\template\loader.py", line 61, in render_to_string
    template = get_template(template_name, using=using)
               ^^^^^^^^^^^^^^^^^^^^^^^^^^^^^^^^^^^^^^^^
  File "D:\-_SHv_4lM\Lib\site-packages\django\template\loader.py", line 15, in get_template
    return engine.get_template(template_name)
           ^^^^^^^^^^^^^^^^^^^^^^^^^^^^^^^^^^
  File "D:\-_SHv_4lM\Lib\site-packages\django\template\backends\django.py", line 79, in get_template
    return Template(self.engine.get_template(template_name), self)
                    ^^^^^^^^^^^^^^^^^^^^^^^^^^^^^^^^^^^^^^^
  File "D:\-_SHv_4lM\Lib\site-packages\django\template\engine.py", line 177, in get_template
    template, origin = self.find_template(template_name)
                       ^^^^^^^^^^^^^^^^^^^^^^^^^^^^^^^^^
  File "D:\-_SHv_4lM\Lib\site-packages\django\template\engine.py", line 159, in find_template
    template = loader.get_template(name, skip=skip)
               ^^^^^^^^^^^^^^^^^^^^^^^^^^^^^^^^^^^^
  File "D:\-_SHv_4lM\Lib\site-packages\django\template\loaders\cached.py", line 57, in get_template
    template = super().get_template(template_name, skip)
               ^^^^^^^^^^^^^^^^^^^^^^^^^^^^^^^^^^^^^^^^^
  File "D:\-_SHv_4lM\Lib\site-packages\django\template\loaders\base.py", line 28, in get_template
    return Template(
           ^^^^^^^^^
  File "D:\-_SHv_4lM\Lib\site-packages\django\template\base.py", line 154, in __init__
    self.nodelist = self.compile_nodelist()
                    ^^^^^^^^^^^^^^^^^^^^^^^
  File "D:\-_SHv_4lM\Lib\site-packages\django\template\base.py", line 196, in compile_nodelist
    nodelist = parser.parse()
               ^^^^^^^^^^^^^^
  File "D:\-_SHv_4lM\Lib\site-packages\django\template\base.py", line 512, in parse
    self.invalid_block_tag(token, command, parse_until)
  File "D:\-_SHv_4lM\Lib\site-packages\django\template\base.py", line 573, in invalid_block_tag
    raise self.error(
django.template.exceptions.TemplateSyntaxError: Invalid block tag on line 7: 'static'. Did you forget to register or load this tag?
ERROR 2024-12-12 14:16:54,251 basehttp "GET /storeapp/cart/ HTTP/1.1" 500 143612
WARNING 2024-12-12 14:20:35,886 log Not Found: /cart
WARNING 2024-12-12 14:20:35,886 basehttp "GET /cart HTTP/1.1" 404 2507
WARNING 2024-12-12 14:20:36,530 log Not Found: /cart
WARNING 2024-12-12 14:20:36,532 basehttp "GET /cart HTTP/1.1" 404 2507
WARNING 2024-12-12 14:20:36,789 log Not Found: /cart
WARNING 2024-12-12 14:20:36,790 basehttp "GET /cart HTTP/1.1" 404 2507
WARNING 2024-12-12 14:20:37,060 log Not Found: /cart
WARNING 2024-12-12 14:20:37,060 basehttp "GET /cart HTTP/1.1" 404 2507
ERROR 2024-12-12 14:22:12,621 log Internal Server Error: /storeapp/cart/
Traceback (most recent call last):
  File "D:\-_SHv_4lM\Lib\site-packages\django\core\handlers\exception.py", line 55, in inner
    response = get_response(request)
               ^^^^^^^^^^^^^^^^^^^^^
  File "D:\-_SHv_4lM\Lib\site-packages\django\core\handlers\base.py", line 204, in _get_response
    self.check_response(response, callback)
  File "D:\-_SHv_4lM\Lib\site-packages\django\core\handlers\base.py", line 332, in check_response
    raise ValueError(
ValueError: The view storeapp.views.cart didn't return an HttpResponse object. It returned None instead.
ERROR 2024-12-12 14:22:12,625 basehttp "POST /storeapp/cart/ HTTP/1.1" 500 71979
ERROR 2024-12-12 14:22:13,411 log Internal Server Error: /storeapp/cart/
Traceback (most recent call last):
  File "D:\-_SHv_4lM\Lib\site-packages\django\core\handlers\exception.py", line 55, in inner
    response = get_response(request)
               ^^^^^^^^^^^^^^^^^^^^^
  File "D:\-_SHv_4lM\Lib\site-packages\django\core\handlers\base.py", line 204, in _get_response
    self.check_response(response, callback)
  File "D:\-_SHv_4lM\Lib\site-packages\django\core\handlers\base.py", line 332, in check_response
    raise ValueError(
ValueError: The view storeapp.views.cart didn't return an HttpResponse object. It returned None instead.
ERROR 2024-12-12 14:22:13,414 basehttp "POST /storeapp/cart/ HTTP/1.1" 500 71979
ERROR 2024-12-12 14:22:13,683 log Internal Server Error: /storeapp/cart/
Traceback (most recent call last):
  File "D:\-_SHv_4lM\Lib\site-packages\django\core\handlers\exception.py", line 55, in inner
    response = get_response(request)
               ^^^^^^^^^^^^^^^^^^^^^
  File "D:\-_SHv_4lM\Lib\site-packages\django\core\handlers\base.py", line 204, in _get_response
    self.check_response(response, callback)
  File "D:\-_SHv_4lM\Lib\site-packages\django\core\handlers\base.py", line 332, in check_response
    raise ValueError(
ValueError: The view storeapp.views.cart didn't return an HttpResponse object. It returned None instead.
ERROR 2024-12-12 14:22:13,686 basehttp "POST /storeapp/cart/ HTTP/1.1" 500 71979
ERROR 2024-12-12 14:22:13,893 log Internal Server Error: /storeapp/cart/
Traceback (most recent call last):
  File "D:\-_SHv_4lM\Lib\site-packages\django\core\handlers\exception.py", line 55, in inner
    response = get_response(request)
               ^^^^^^^^^^^^^^^^^^^^^
  File "D:\-_SHv_4lM\Lib\site-packages\django\core\handlers\base.py", line 204, in _get_response
    self.check_response(response, callback)
  File "D:\-_SHv_4lM\Lib\site-packages\django\core\handlers\base.py", line 332, in check_response
    raise ValueError(
ValueError: The view storeapp.views.cart didn't return an HttpResponse object. It returned None instead.
ERROR 2024-12-12 14:22:13,896 basehttp "POST /storeapp/cart/ HTTP/1.1" 500 71979
ERROR 2024-12-12 14:22:14,034 log Internal Server Error: /storeapp/cart/
Traceback (most recent call last):
  File "D:\-_SHv_4lM\Lib\site-packages\django\core\handlers\exception.py", line 55, in inner
    response = get_response(request)
               ^^^^^^^^^^^^^^^^^^^^^
  File "D:\-_SHv_4lM\Lib\site-packages\django\core\handlers\base.py", line 204, in _get_response
    self.check_response(response, callback)
  File "D:\-_SHv_4lM\Lib\site-packages\django\core\handlers\base.py", line 332, in check_response
    raise ValueError(
ValueError: The view storeapp.views.cart didn't return an HttpResponse object. It returned None instead.
ERROR 2024-12-12 14:22:14,036 basehttp "POST /storeapp/cart/ HTTP/1.1" 500 71979
